<?xml version="1.0" ?>
<!-- =================================================================================== -->
<!-- |    This document was autogenerated by xacro from irb4400l_30_243.xacro          | -->
<!-- |    EDITING THIS FILE BY HAND IS NOT RECOMMENDED                                 | -->
<!-- =================================================================================== -->
<robot name="abb_irb4400l_30_243" xmlns:xacro="http://wiki.ros.org/xacro">
  <!-- Conversion were obtained from http://www.e-paint.co.uk/Lab_values.asp
       unless otherwise stated. -->
  <!-- link list 

  <gazebo>
    <plugin filename="libgazebo_ros_control.so" name="ros_control">
    </plugin>
  </gazebo>-->
    

  <link name="base_link">
    <visual>
      <origin rpy="0 0 0" xyz="0 0 0"/>
      <geometry>
        <mesh filename="package://abb_irb4400_support/meshes/irb4400l_30_243/visual/base_link.stl"/>
      </geometry>
      <material name="">
        <color rgba="0.7372549 0.3490196 0.1607843 1"/>
      </material>
    </visual>
    <collision>
      <geometry>
        <mesh filename="package://abb_irb4400_support/meshes/irb4400l_30_243/collision/base_link.stl"/>
      </geometry>
      <material name="">
        <color rgba="1 1 0 1"/>
      </material>
    </collision>
    <inertial>
      <mass value="60.266"/>
      <inertia ixx="2.13" ixy="0.0" ixz="0.0" iyy="2.665" iyz="0.0" izz="3.587"/>
    </inertial>


  </link>
  <link name="link_1">
    <visual>
      <origin rpy="0 0 0" xyz="0 0 0"/>
      <geometry>
        <mesh filename="package://abb_irb4400_support/meshes/irb4400l_30_243/visual/link_1.stl"/>
      </geometry>
      <material name="">
        <color rgba="0.7372549 0.3490196 0.1607843 1"/>
      </material>
    </visual>
    <collision>
      <origin rpy="0 0 0" xyz="0 0 0"/>
      <geometry>
        <mesh filename="package://abb_irb4400_support/meshes/irb4400l_30_243/collision/link_1.stl"/>
      </geometry>
      <material name="">
        <color rgba="1 1 0 1"/>
      </material>
    </collision>
    <inertial>
      <mass value="242.08"/>
      <inertia ixx="81.641" ixy="0.0" ixz="0.0" iyy="77.029" iyz="0.0" izz="27.631"/>
    </inertial>
  </link>
  <link name="link_2">
    <visual>
      <origin rpy="0 0 0" xyz="0 0 0"/>
      <geometry>
        <mesh filename="package://abb_irb4400_support/meshes/irb4400l_30_243/visual/link_2.stl"/>
      </geometry>
      <material name="">
        <color rgba="0.7372549 0.3490196 0.1607843 1"/>
      </material>
    </visual>
    <collision>
      <origin rpy="0 0 0" xyz="0 0 0"/>
      <geometry>
        <mesh filename="package://abb_irb4400_support/meshes/irb4400l_30_243/collision/link_2.stl"/>
      </geometry>
      <material name="">
        <color rgba="1 1 0 1"/>
      </material>
    </collision>
    <inertial>
      <mass value="108.861"/>
      <inertia ixx="187.884" ixy="0.0" ixz="0.0" iyy="198.517" iyz="0.0" izz="12.300"/>
    </inertial>
  </link>
  <link name="link_3">
    <visual>
      <origin rpy="0 0 0" xyz="0 0 0"/>
      <geometry>
        <mesh filename="package://abb_irb4400_support/meshes/irb4400l_30_243/visual/link_3.stl"/>
      </geometry>
      <material name="">
        <color rgba="0.7372549 0.3490196 0.1607843 1"/>
      </material>
    </visual>
    <collision>
      <origin rpy="0 0 0" xyz="0 0 0"/>
      <geometry>
        <mesh filename="package://abb_irb4400_support/meshes/irb4400l_30_243/collision/link_3.stl"/>
      </geometry>
      <material name="">
        <color rgba="1 1 0 1"/>
      </material>
    </collision>
    <inertial>
      <mass value="131.343"/>
      <inertia ixx="584.225" ixy="0.0" ixz="0.0" iyy="688.283" iyz="0.0" izz="108.136"/>
    </inertial>
  </link>
  <!-- start new link -->
  <link name="link_4n">
    <visual>
      <geometry>
        <cylinder length="0.8" radius="0.05"/>
      </geometry>
      <origin rpy="0 1.57 0" xyz="0 0 0"/>
      <material name="">
        <color rgba="0.7372549 0.3490196 0.1607843 1"/>
      </material>
    </visual>
    <collision>
      <geometry>
        <cylinder length="0.8" radius="0.05"/>
      </geometry>
    </collision>
    <inertial>
      <mass value="5.696"/>
      <inertia ixx="24.452" ixy="0.0" ixz="0.0" iyy="45.056" iyz="0.0" izz="20.617"/>
    </inertial>
  </link>
  <!-- 0.8 metro de largo. -->
  <!-- diametro 160.000 mm-->
  <!-- end new link -->
  <link name="link_4">
    <visual>
      <origin rpy="0 0 0" xyz="0 0 0"/>
      <geometry>
        <mesh filename="package://abb_irb4400_support/meshes/irb4400l_30_243/visual/link_4.stl"/>
      </geometry>
      <material name="">
        <color rgba="0.7372549 0.3490196 0.1607843 1"/>
      </material>
    </visual>
    <collision>
      <origin rpy="0 0 0" xyz="0 0 0"/>
      <geometry>
        <mesh filename="package://abb_irb4400_support/meshes/irb4400l_30_243/collision/link_4.stl"/>
      </geometry>
      <material name="">
        <color rgba="1 1 0 1"/>
      </material>
    </collision>
    <inertial>
      <mass value="1.687"/>
      <inertia ixx="7.352" ixy="0.0" ixz="0.0" iyy="15.456" iyz="0.0" izz="8.111"/>
    </inertial>
  </link>
  <link name="link_5">
    <visual>
      <origin rpy="0 0 0" xyz="0 0 0"/>
      <geometry>
        <mesh filename="package://abb_irb4400_support/meshes/irb4400l_30_243/visual/link_5.stl"/>
      </geometry>
      <material name="">
        <color rgba="0.7372549 0.3490196 0.1607843 1"/>
      </material>
    </visual>
    <collision>
      <origin rpy="0 0 0" xyz="0 0 0"/>
      <geometry>
        <mesh filename="package://abb_irb4400_support/meshes/irb4400l_30_243/collision/link_5.stl"/>
      </geometry>
      <material name="">
        <color rgba="1 1 0 1"/>
      </material>
    </collision>
    <inertial>
      <mass value="2.918"/>
      <inertia ixx="12.210" ixy="0.0" ixz="0.0" iyy="27.389" iyz="0.0" izz="15.193"/>
    </inertial>
  </link>
  <link name="link_6">
    <visual>
      <origin rpy="0 0 0" xyz="0 0 0"/>
      <geometry>
        <mesh filename="package://abb_irb4400_support/meshes/irb4400l_30_243/visual/link_6.stl"/>
      </geometry>
      <material name="">
        <color rgba="0.1882353 0.1960784 0.2039216 1"/>
      </material>
    </visual>
    <collision>
      <origin rpy="0 0 0" xyz="0 0 0"/>
      <geometry>
        <mesh filename="package://abb_irb4400_support/meshes/irb4400l_30_243/collision/link_6.stl"/>
      </geometry>
      <material name="">
        <color rgba="1 1 0 1"/>
      </material>
    </collision>
    <inertial>
      <mass value="0.683"/>
      <inertia ixx="0.684" ixy="0.0" ixz="0.0" iyy="1.612" iyz="0.0" izz="0.93"/>
    </inertial>
  </link>
  <link name="tool0"/>
  <!-- end of link list -->
  <!-- joint list -->
  <joint name="joint_1" type="revolute">
    <origin rpy="0 0 0" xyz="0 0 0"/>
    <parent link="base_link"/>
    <child link="link_1"/>
    <axis xyz="0 0 1"/>
    <limit effort="150.0" lower="-2.87979" upper="2.87979" velocity="2.618"/>
    <dynamics damping="0.0" friction="0.0"/>
  </joint>
  <joint name="joint_2" type="revolute">
    <origin rpy="0 0 0" xyz="0.2 0 0.68"/>
    <parent link="link_1"/>
    <child link="link_2"/>
    <axis xyz="0 1 0"/>
    <limit effort="150.0" lower="-1.2217" upper="1.658" velocity="2.0944"/>
    <dynamics damping="0.0" friction="0.0"/>
  </joint>
  <joint name="joint_3" type="revolute">
    <origin rpy="0 0 0" xyz="0 0 0.89"/>
    <parent link="link_2"/>
    <child link="link_3"/>
    <axis xyz="0 1 0"/>
    <limit effort="150.0" lower="-1.0472" upper="1.1345" velocity="2.0944"/>
    <dynamics damping="0.0" friction="0.0"/>
  </joint>
  <joint name="joint_4" type="revolute">
    <origin rpy="0 0 0" xyz="0.63 0 0.15"/>
    <parent link="link_3"/>
    <child link="link_4n"/>
    <axis xyz="1 0 0"/>
    <limit effort="150.0" lower="-3.49" upper="3.49" velocity="3.927"/>
    <dynamics damping="0.0" friction="0.0"/>
  </joint>
  <!-- .............................................................................. -->
  <!-- joinit new -->
  <joint name="joint_4n" type="prismatic">
    <parent link="link_4n"/>
    <child link="link_4"/>
    <origin rpy="0 0 0" xyz="1.10 0 0"/>
    <axis xyz="1 0 0"/>
    <limit effort="150.0" lower="-0.35" upper="0.35" velocity="0.1"/>
    <dynamics damping="0.0" friction="0.0"/>
  </joint>
  <!-- joint new end -->
  <!-- .............................................................................. -->
  <joint name="joint_5" type="revolute">
    <origin rpy="0 0 0" xyz="0 0 0"/>
    <parent link="link_4"/>
    <child link="link_5"/>
    <axis xyz="0 1 0"/>
    <limit effort="150.0" lower="-2.0944" upper="2.0944" velocity="4.3633"/>
    <dynamics damping="0.0" friction="0.0"/>
  </joint>
  <joint name="joint_6" type="revolute">
    <origin rpy="0 0 0" xyz="0 0 0"/>
    <parent link="link_5"/>
    <child link="link_6"/>
    <axis xyz="1 0 0"/>
    <limit effort="150.0" lower="-6.9813" upper="6.9813" velocity="5.7596"/>
    <dynamics damping="0.0" friction="0.0"/>
  </joint>
  <joint name="joint_6-tool0" type="fixed">
    <parent link="link_6"/>
    <child link="tool0"/>
    <origin rpy="0 0 0" xyz="0.14 0 0"/>
  </joint>
  <!-- end of joint list -->

 
  <!--Transmisions-->

  <transmission name="joint1_trans">
    <type>transmission_interface/SimpleTransmission</type>
    <joint name="joint_1">
      <hardwareInterface>hardware_interface/PositionJointInterface</hardwareInterface>
    </joint>
    <actuator name="joint1_motor">
      <mechanicalReduction>1</mechanicalReduction>
    </actuator>
  </transmission>

  <transmission name="joint2_trans">
    <type>transmission_interface/SimpleTransmission</type>
    <joint name="joint_2">
      <hardwareInterface>hardware_interface/PositionJointInterface</hardwareInterface>
    </joint>
    <actuator name="joint2_motor">
      <mechanicalReduction>1</mechanicalReduction>
    </actuator>
  </transmission>


  <transmission name="joint3_trans">
    <type>transmission_interface/SimpleTransmission</type>
    <joint name="joint_3">
      <hardwareInterface>hardware_interface/PositionJointInterface</hardwareInterface>
    </joint>
    <actuator name="joint3_motor">
      <mechanicalReduction>1</mechanicalReduction>
    </actuator>
  </transmission>


  <transmission name="joint4_trans">
    <type>transmission_interface/SimpleTransmission</type>
    <joint name="joint_4">
      <hardwareInterface>hardware_interface/PositionJointInterface</hardwareInterface>
    </joint>
    <actuator name="joint4_motor">
      <mechanicalReduction>1</mechanicalReduction>
    </actuator>
  </transmission>

  <transmission name="joint4n_trans">
    <type>transmission_interface/SimpleTransmission</type>
    <joint name="joint_4n">
      <hardwareInterface>hardware_interface/PositionJointInterface</hardwareInterface>
    </joint>
    <actuator name="joint4n_motor">
      <mechanicalReduction>1</mechanicalReduction>
    </actuator>
  </transmission>

  <transmission name="joint5_trans">
    <type>transmission_interface/SimpleTransmission</type>
    <joint name="joint_5">
      <hardwareInterface>hardware_interface/PositionJointInterface</hardwareInterface>
    </joint>
    <actuator name="joint5_motor">
      <mechanicalReduction>1</mechanicalReduction>
    </actuator>
  </transmission>

  <transmission name="joint6_trans">
    <type>transmission_interface/SimpleTransmission</type>
    <joint name="joint_6">
      <hardwareInterface>hardware_interface/PositionJointInterface</hardwareInterface>
    </joint>
    <actuator name="joint6_motor">
      <mechanicalReduction>1</mechanicalReduction>
    </actuator>
  </transmission>

  <gazebo reference="base_link">
    <selfCollide>true</selfCollide>
  </gazebo>
  <gazebo reference="link_1">
    <selfCollide>true</selfCollide>
  </gazebo>
  <gazebo reference="link_2">
    <selfCollide>true</selfCollide>
  </gazebo>
  <gazebo reference="link_3">
    <selfCollide>true</selfCollide>
  </gazebo>
  <gazebo reference="link_4">
    <selfCollide>true</selfCollide>
  </gazebo>
  <gazebo reference="link_4n">
    <selfCollide>true</selfCollide>
  </gazebo>
  <gazebo reference="link_5">
    <selfCollide>true</selfCollide>
  </gazebo>
  <gazebo reference="link_6">
    <selfCollide>true</selfCollide>
  </gazebo>

  <!-- <link name="world"/> -->
  <link name="world">
    <inertial>
      <mass value="0.0000001"/>
      <origin rpy="0 0 0" xyz="0.0 0.0 0.0"/>
      <inertia ixx="0.0000001" ixy="0.0" ixz="0.0" iyy="0.0000001" iyz="0.0" izz="0.0000001"/>
    </inertial>
  </link>
    
  <joint name="world_joint" type="fixed">
    <parent link="world"/>
    <child link="base_link"/>
    <origin rpy="0.0 0.0 0.0" xyz="0.0 0.0 0.0"/>
  </joint>

  <!-- Gazebo plugin for ROS Control -->
  <gazebo>
    <plugin name="gazebo_ros_control" filename="libgazebo_ros_control.so">
      <robotNamespace>/</robotNamespace>
    </plugin>
  </gazebo> 

</robot>

